import { connect, NatsError, REQ_TIMEOUT } from 'nats'
import { ProviderRef, ProviderContext, ErrorWithCatch } from 'nnms'
import { Observable, merge, fromEvent, throwError } from 'rxjs'
import { mergeMap, first, map } from 'rxjs/operators'

const NATS_VARS = {
  URL: 'nats://localhost:4222'
}

@ProviderRef('nats', NATS_VARS)
export class NatsProvider {
  constructor(
    private _ctx: ProviderContext<typeof NATS_VARS>
  ) { }

  private readonly _client = connect({url: this._ctx.vars.URL, json: true})

  readonly init = this._init()

  publish<T>(subject: string, msg: T): Promise<void> {
    return new Promise((resolve, reject) => (
      this._client.publish(subject, msg, (err: Error) => err ? reject(err) : resolve())
    ))
  }

  watch<T>(subject: string): Observable<T> {
    return new Observable(subscriber => {
      const sid = this._client.subscribe(subject, (e: T) => subscriber.next(e))
      return () => this._client.unsubscribe(sid)
    })
  }

  requestOnce<R>(subject: string, body: {}, timeout = 10800): Promise<R> {
    return new Promise((resolve, reject) => {
      this._client.requestOne(subject, body, timeout, (res: R |NatsError) => {
        if (res instanceof NatsError && res.code === REQ_TIMEOUT) {
          const err = new ErrorWithCatch(`Request failed '${subject}': ${res.message}`, res.chainedError)
          this._ctx.logger.error('REQUEST_FAILED', err)
          return reject(err)
        }
        resolve(res as R)
      })
    })
  }

  async subscribeRequest<T>(subject: string, handler: (e: T) => any): Promise<number> {
    return this._client.subscribe(subject, async (e: T, replyTo: string) => {
      let result: any
      try {
        result = await handler(e)
      } catch (catched) {
        result = new NatsError(`handler for subject '${subject}' failed`, 'HANDLER_FAILURE')
        this._ctx.logger.error(result.message, catched)
      }
      this._client.publish(replyTo, result);
    })
  }

  private async _init(): Promise<void> {
    try {
      await this._connect()
    } catch (err) {
      console.log(err)
      process.exit(1)
      this._ctx.logger.error('FAILED_CONNECTION', err.message)
      throw err
    }
    this._ctx.logger.info(`CLIENT_LISTENING`,Â {url: this._ctx.vars.URL})
  }

  private _connect(): Promise<void> {
    const connectEvents = [
      fromEvent(this._client, 'connect').pipe(map(() => { })),
      fromEvent(this._client, 'error').pipe(mergeMap(err => throwError(err)))
    ]
    return merge(...connectEvents).pipe(first()).toPromise()
  }
}

export default NatsProvider
